Workbook

Sheet 2C 2B ครั้งที่ 1
A1: ตารางบันทึกคะแนน สอบความรู้ในงาน SUPERVISOR ครั้งที่ 1 /2568
A2: ลำดับ | B2: ID | C2: ชื่อ - สกุล | D2: ISO | E2: ความรู้ทั่วไป | F2: CASH | G2: GRAND TOTAL | H2: TOTAL | I2: TOTAL | J2: หมายเหตุ
D3: 60 | E3: 40 | F3: 30 | G3: =SUM(D3:F3) -> 130 | H3: 100 | I3: 100
A4: 1 | B4: 1730 | C4: นางอมร ทฤษฎี | D4: 56 | E4: 34 | F4: 26 | G4: =SUM(D4:F4) -> 116 | H4: =G4*$H$3/$G$3 -> 89.230769 | I4: =CEILING(H4,0.5) -> 89.5 | J4: ไม่ผ่าน
A5: 2 | B5: 5540 | C5: นางสาวกนิษฐา ศรีอาภัย | D5: 60 | E5: 38 | F5: 29 | G5: =SUM(D5:F5) -> 127 | H5: =G5*$H$3/$G$3 -> 97.692308 | I5: =CEILING(H5,0.5) -> 98
A6: 3 | B6: 9038 | C6: นางสาวทสพร ทองทา | D6: 60 | E6: 39 | F6: 29 | G6: =SUM(D6:F6) -> 128 | H6: =G6*$H$3/$G$3 -> 98.461538 | I6: =CEILING(H6,0.5) -> 98.5
A7: 4 | B7: 12324 | C7: นางสาวสุรัสสา ผาสุข | D7: 58 | E7: 38 | F7: 26 | G7: =SUM(D7:F7) -> 122 | H7: =G7*$H$3/$G$3 -> 93.846154 | I7: =CEILING(H7,0.5) -> 94
A8: 5 | B8: 18512 | C8: นางสาวจุติพร สุญาสิทธิ์ | D8: 60 | E8: 37 | F8: 27 | G8: =SUM(D8:F8) -> 124 | H8: =G8*$H$3/$G$3 -> 95.384615 | I8: =CEILING(H8,0.5) -> 95.5
A10: =SUBTOTAL(3,$B$10:$B10)*1 -> 1 | B10: 3429 | C10: นางสาวอภิญญา หลิ่วน้อย | D10: 54 | E10: 37 | F10: 29 | G10: =SUM(D10:F10) -> 120 | H10: =G10*$H$3/$G$3 -> 92.307692 | I10: =CEILING(H10,0.5) -> 92.5
A11: =SUBTOTAL(3,$B$10:$B11)*1 -> 2 | B11: 3643 | C11: นางกัญญาภัค ศุภมนตรี | D11: 58 | E11: 39 | F11: 24 | G11: =SUM(D11:F11) -> 121 | H11: =G11*$H$3/$G$3 -> 93.076923 | I11: =CEILING(H11,0.5) -> 93.5
A12: =SUBTOTAL(3,$B$10:$B12)*1 -> 3 | B12: 4843 | C12: นางสาวรุ่งเรือง หงษ์ลอย | D12: 54 | E12: 38 | F12: 28 | G12: =SUM(D12:F12) -> 120 | H12: =G12*$H$3/$G$3 -> 92.307692 | I12: =CEILING(H12,0.5) -> 92.5
A13: =SUBTOTAL(3,$B$10:$B13)*1 -> 4 | B13: 5209 | C13: นางสาวจิราภรณ์ ทองบุญ | D13: 56 | E13: 40 | F13: 29 | G13: =SUM(D13:F13) -> 125 | H13: =G13*$H$3/$G$3 -> 96.153846 | I13: =CEILING(H13,0.5) -> 96.5
A14: =SUBTOTAL(3,$B$10:$B14)*1 -> 5 | B14: 5258 | C14: นางปรียาภรณ์ ขำสงค์ชัยเจริญ | D14: 58 | E14: 36 | F14: 29 | G14: =SUM(D14:F14) -> 123 | H14: =G14*$H$3/$G$3 -> 94.615385 | I14: =CEILING(H14,0.5) -> 95
A15: =SUBTOTAL(3,$B$10:$B15)*1 -> 6 | B15: 5994 | C15: นางสาวกชพร กลั่นสวน | D15: 54/60 | E15: 34/37 | F15: 28/30 | G15: 116/127 | H15: 89.230769 | I15: 89.5/98 | J15: ซ่อมผ่าน
A16: =SUBTOTAL(3,$B$10:$B16)*1 -> 7 | B16: 7898 | C16: นางสาวศรัณยา ลีละภมรกิจ | D16: 54 | E16: 39 | F16: 24 | G16: =SUM(D16:F16) -> 117 | H16: =G16*$H$3/$G$3 -> 90 | I16: =CEILING(H16,0.5) -> 90
A17: =SUBTOTAL(3,$B$10:$B17)*1 -> 8 | B17: 11467 | C17: นางสาวกรรณิกา มีมุข | D17: 60 | E17: 39 | F17: 30 | G17: =SUM(D17:F17) -> 129 | H17: =G17*$H$3/$G$3 -> 99.230769 | I17: =CEILING(H17,0.5) -> 99.5
A18: =SUBTOTAL(3,$B$10:$B18)*1 -> 9 | B18: 12047 | C18: นางสาวอัญชลี ปั้นแตง | D18: 60 | E18: 38 | F18: 26 | G18: =SUM(D18:F18) -> 124 | H18: =G18*$H$3/$G$3 -> 95.384615 | I18: =CEILING(H18,0.5) -> 95.5
A19: =SUBTOTAL(3,$B$10:$B19)*1 -> 10 | B19: 12259 | C19: นางสาวมนธิชา จันทะผล | D19: 60 | E19: 40 | F19: 30 | G19: =SUM(D19:F19) -> 130 | H19: =G19*$H$3/$G$3 -> 100 | I19: =CEILING(H19,0.5) -> 100 | J19: สอบหลังจากวันที่กำหนด
A20: =SUBTOTAL(3,$B$10:$B20)*1 -> 11 | B20: 17151 | C20: นางสาวภัทรณัฏฐ์ ขจรพัชรสกุล | D20: 54 | E20: 36 | F20: 29 | G20: =SUM(D20:F20) -> 119 | H20: =G20*$H$3/$G$3 -> 91.538462 | I20: =CEILING(H20,0.5) -> 92
A21: =SUBTOTAL(3,$B$10:$B21)*1 -> 12 | B21: 19197 | C21: นางสาวเกตุวดี จูเกตุ | D21: 56 | E21: 39 | F21: 28 | G21: =SUM(D21:F21) -> 123 | H21: =G21*$H$3/$G$3 -> 94.615385 | I21: =CEILING(H21,0.5) -> 95
A22: =SUBTOTAL(3,$B$10:$B22)*1 -> 13 | B22: 25647 | C22: นางสาวรุ่งรัตน์ ดาวไธสง | D22: 54 | E22: 38 | F22: 27 | G22: =SUM(D22:F22) -> 119 | H22: =G22*$H$3/$G$3 -> 91.538462 | I22: =CEILING(H22,0.5) -> 92
A23: =SUBTOTAL(3,$B$10:$B23)*1 -> 14 | B23: 33577 | C23: นางสาวอรสุรางค์ ภาคบูรณ์ | D23: 60 | E23: 38 | F23: 29 | G23: =SUM(D23:F23) -> 127 | H23: =G23*$H$3/$G$3 -> 97.692308 | I23: =CEILING(H23,0.5) -> 98
A24: =SUBTOTAL(3,$B$10:$B24)*1 -> 15 | B24: 32901 | C24: นางสาวประภาพร มากเจริญ | D24: 58 | E24: 38 | F24: 29 | G24: =SUM(D24:F24) -> 125 | H24: =G24*$H$3/$G$3 -> 96.153846 | I24: =CEILING(H24,0.5) -> 96.5
A25: =SUBTOTAL(3,$B$10:$B25)*1 -> 16 | B25: 35911 | C25: นางสาวพิชญ์ชิชา หาญธีรวิรสร์ | D25: 54 | E25: 39 | F25: 30 | G25: =SUM(D25:F25) -> 123 | H25: =G25*$H$3/$G$3 -> 94.615385 | I25: =CEILING(H25,0.5) -> 95
A26: =SUBTOTAL(3,$B$10:$B26)*1 -> 17 | B26: 62885 | C26: นางสาวศุภวรรณ แดงทอง | D26: 60 | E26: 38 | F26: 29 | G26: =SUM(D26:F26) -> 127 | H26: =G26*$H$3/$G$3 -> 97.692308 | I26: =CEILING(H26,0.5) -> 98
A27: =SUBTOTAL(3,$B$10:$B27)*1 -> 18 | B27: 37439 | C27: นางสาวนภัสวรรณ ชะฎาจิตร | D27: 60 | E27: 39 | F27: 29 | G27: =SUM(D27:F27) -> 128 | H27: =G27*$H$3/$G$3 -> 98.461538 | I27: =CEILING(H27,0.5) -> 98.5
A28: =SUBTOTAL(3,$B$10:$B28)*1 -> 19 | B28: 37441 | C28: นางสาวกัญศิธณุวัน กาญจน์ศิฐกุล | D28: 60 | E28: 39 | F28: 29 | G28: =SUM(D28:F28) -> 128 | H28: =G28*$H$3/$G$3 -> 98.461538 | I28: =CEILING(H28,0.5) -> 98.5

Sheet 1B 1A ครั้งที่ 1
A1: ตารางบันทึกคะแนน สอบความรู้ในงาน CASHIER 1B 1A ครั้งที่ 1 /2568
A2: ลำดับ | B2: ID | C2: ชื่อ - สกุล | D2: ISO | E2: ความรู้ทั่วไป | F2: CASH | G2: GRAND TOTAL | H2: TOTAL | I2: TOTAL | J2: หมายเหตุ | K2: ไม่ร่วมโครงการ
D3: 60 | E3: 40 | F3: 30 | G3: =SUM(D3:F3) -> 130 | H3: 100 | I3: 100
A4: =SUBTOTAL(3,$B4:$B$4)*1 -> 1 | B4: 1633 | C4: นางสาวสมใจ ปุกจันทึก | D4: 52 | E4: 37 | F4: 29 | G4: =SUM(D4:F4) -> 118 | H4: =G4*$H$3/$G$3 -> 90.769231 | I4: =CEILING(H4,0.5) -> 91
A5: =SUBTOTAL(3,$B$4:$B5)*1 -> 2 | B5: 2117 | C5: นางสาวบุญจิรา ไสยยา | D5: 60 | E5: 38 | F5: 30 | G5: =SUM(D5:F5) -> 128 | H5: =G5*$H$3/$G$3 -> 98.461538 | I5: =CEILING(H5,0.5) -> 98.5
A6: =SUBTOTAL(3,$B$4:$B6)*1 -> 3 | B6: 3031 | C6: นางสาวกาญจนา บุญมา | D6: 58 | E6: 37 | F6: 28 | G6: =SUM(D6:F6) -> 123 | H6: =G6*$H$3/$G$3 -> 94.615385 | I6: =CEILING(H6,0.5) -> 95 | J6: สอบหลังจากวันที่กำหนด
A7: =SUBTOTAL(3,$B$4:$B7)*1 -> 4 | B7: 7366 | C7: นางเบญจา คำชนะ | D7: 54 | E7: 40 | F7: 30 | G7: =SUM(D7:F7) -> 124 | H7: =G7*$H$3/$G$3 -> 95.384615 | I7: =CEILING(H7,0.5) -> 95.5 | K7: ลาป่วยเกิน 30 วัน
A8: =SUBTOTAL(3,$B$4:$B8)*1 -> 5 | B8: 13445 | C8: นางทรรศนียา หลงคำรัตน์ | D8: 56 | E8: 40 | F8: 30 | G8: =SUM(D8:F8) -> 126 | H8: =G8*$H$3/$G$3 -> 96.923077 | I8: =CEILING(H8,0.5) -> 97
A9: =SUBTOTAL(3,$B$4:$B9)*1 -> 6 | B9: 22954 | C9: นางสาวกาญจนา ถาวรวัน | D9: 58 | E9: 40 | F9: 30 | G9: =SUM(D9:F9) -> 128 | H9: =G9*$H$3/$G$3 -> 98.461538 | I9: =CEILING(H9,0.5) -> 98.5
A10: =SUBTOTAL(3,$B$4:$B10)*1 -> 7 | B10: 34500 | C10: นางสาวนิศารัตน์ นาสันเทียะ | D10: 60 | E10: 40 | F10: 29 | G10: =SUM(D10:F10) -> 129 | H10: =G10*$H$3/$G$3 -> 99.230769 | I10: =CEILING(H10,0.5) -> 99.5
A11: =SUBTOTAL(3,$B$4:$B11)*1 -> 8 | B11: 35518 | C11: นางวราพรรณ คงธน | D11: 56 | E11: 38 | F11: 27 | G11: =SUM(D11:F11) -> 121 | H11: =G11*$H$3/$G$3 -> 93.076923 | I11: =CEILING(H11,0.5) -> 93.5 | J11: สอบก่อน
A12: =SUBTOTAL(3,$B$4:$B12)*1 -> 9 | B12: 35528 | C12: นางสาวศุภลักษณ์ วงษ์ชาชม | D12: 58 | E12: 40 | F12: 30 | G12: =SUM(D12:F12) -> 128 | H12: =G12*$H$3/$G$3 -> 98.461538 | I12: =CEILING(H12,0.5) -> 98.5
A13: =SUBTOTAL(3,$B$4:$B13)*1 -> 10 | B13: 35529 | C13: นางสาวปัทมา ชื่นทองคำ | D13: 54 | E13: 40 | F13: 29 | G13: =SUM(D13:F13) -> 123 | H13: =G13*$H$3/$G$3 -> 94.615385 | I13: =CEILING(H13,0.5) -> 95
A14: =SUBTOTAL(3,$B$4:$B14)*1 -> 11 | B14: 38834 | C14: นางสาวสุภาวดี เอี่ยมอารยกุล | D14: 60 | E14: 40 | F14: 30 | G14: =SUM(D14:F14) -> 130 | H14: =G14*$H$3/$G$3 -> 100 | I14: =CEILING(H14,0.5) -> 100
A15: =SUBTOTAL(3,$B$4:$B15)*1 -> 12 | B15: 60869 | C15: นางสาวธัญญรัตน์ นาคำ | D15: 56 | E15: 40 | F15: 29 | G15: =SUM(D15:F15) -> 125 | H15: =G15*$H$3/$G$3 -> 96.153846 | I15: =CEILING(H15,0.5) -> 96.5
A16: =SUBTOTAL(3,$B$4:$B16)*1 -> 13 | B16: 60886 | C16: นางสาวการสดา สังฆะศรี | D16: 44/56 | E16: 39/40 | F16: 27/30 | G16: 110/126 | H16: 84.615385 | I16: 85/97 | J16: ซ่อมผ่าน
A17: =SUBTOTAL(3,$B$4:$B17)*1 -> 14 | B17: 60890 | C17: นางสาวกัญญาพัชร เสาะแสวง | D17: 58 | E17: 39 | F17: 29 | G17: =SUM(D17:F17) -> 126 | H17: =G17*$H$3/$G$3 -> 96.923077 | I17: =CEILING(H17,0.5) -> 97 | J17: สอบก่อน
A18: =SUBTOTAL(3,$B$4:$B18)*1 -> 15 | B18: 61826 | C18: นางสาวปาริชาติ จันทร์ขาว | D18: 60 | E18: 40 | F18: 30 | G18: =SUM(D18:F18) -> 130 | H18: =G18*$H$3/$G$3 -> 100 | I18: =CEILING(H18,0.5) -> 100
A19: =SUBTOTAL(3,$B$4:$B19)*1 -> 16 | B19: 62366 | C19: นางสาวประภากร บำรุงกุล | D19: 58 | E19: 35 | F19: 30 | G19: =SUM(D19:F19) -> 123 | H19: =G19*$H$3/$G$3 -> 94.615385 | I19: =CEILING(H19,0.5) -> 95
A20: =SUBTOTAL(3,$B$4:$B20)*1 -> 17 | B20: 62442 | C20: นายธัญวุฒิ สมยันพล | D20: 60 | E20: 38 | F20: 29 | G20: =SUM(D20:F20) -> 127 | H20: =G20*$H$3/$G$3 -> 97.692308 | I20: =CEILING(H20,0.5) -> 98 | J20: สอบก่อน
A21: =SUBTOTAL(3,$B$4:$B21)*1 -> 18 | B21: 62454 | C21: นายปัณณวิชญ์ อิสรากมลพัฒน์ | D21: 56/58 | E21: 28/40 | F21: 19/29 | G21: 103/127 | H21: 79.230769 | I21: 79.5/98 | J21: ซ่อมผ่าน
A22: =SUBTOTAL(3,$B$4:$B22)*1 -> 19 | B22: 62559 | C22: นางสาวกมลทิพย์ อาจกลาง | D22: 58 | E22: 39 | F22: 30 | G22: =SUM(D22:F22) -> 127 | H22: =G22*$H$3/$G$3 -> 97.692308 | I22: =CEILING(H22,0.5) -> 98 | J22: สอบก่อน
A23: =SUBTOTAL(3,$B$4:$B23)*1 -> 20 | B23: 62679 | C23: นางสาววิชุดา ตีบจันทร์ | D23: 58 | E23: 40 | F23: 30 | G23: =SUM(D23:F23) -> 128 | H23: =G23*$H$3/$G$3 -> 98.461538 | I23: =CEILING(H23,0.5) -> 98.5
A24: =SUBTOTAL(3,$B$4:$B24)*1 -> 21 | B24: 62681 | C24: นางสาววรัญญา ปันแปง | D24: 38/58 | E24: 37/38 | F24: 29/30 | G24: 104/126 | H24: 80 | I24: 80/97 | J24: ซ่อมผ่าน
A25: =SUBTOTAL(3,$B$4:$B25)*1 -> 22 | B25: 62736 | C25: นางสาววิภาดา ชูรัตน์ | D25: 58 | E25: 40 | F25: 29 | G25: =SUM(D25:F25) -> 127 | H25: =G25*$H$3/$G$3 -> 97.692308 | I25: =CEILING(H25,0.5) -> 98
A26: =SUBTOTAL(3,$B$4:$B26)*1 -> 23 | B26: 62741 | C26: นางสาวสุเมทา พรหมดี | D26: 48/56 | E26: 37/40 | F26: 30/30 | G26: 115/126 | H26: 88.461538 | I26: 88.5/97 | J26: ซ่อมผ่าน
A27: =SUBTOTAL(3,$B$4:$B27)*1 -> 24 | B27: 62810 | C27: นางสาวพลอยไพลิน เวทนา | D27: 60 | E27: 39 | F27: 30 | G27: =SUM(D27:F27) -> 129 | H27: =G27*$H$3/$G$3 -> 99.230769 | I27: =CEILING(H27,0.5) -> 99.5
A28: =SUBTOTAL(3,$B$4:$B28)*1 -> 25 | B28: 62882 | C28: นางสาวสุนิศา มูลชัย | D28: 58 | E28: 39 | F28: 29 | G28: =SUM(D28:F28) -> 126 | H28: =G28*$H$3/$G$3 -> 96.923077 | I28: =CEILING(H28,0.5) -> 97
A29: =SUBTOTAL(3,$B$4:$B29)*1 -> 26 | B29: 62952 | C29: นางสาวรัฐติกาล จิตต์พรหม | D29: 60 | E29: 38 | F29: 30 | G29: =SUM(D29:F29) -> 128 | H29: =G29*$H$3/$G$3 -> 98.461538 | I29: =CEILING(H29,0.5) -> 98.5
A30: =SUBTOTAL(3,$B$4:$B30)*1 -> 27 | B30: 62954 | C30: นางสาวปานชนก สุขโข | D30: 60 | E30: 39 | F30: 28 | G30: =SUM(D30:F30) -> 127 | H30: =G30*$H$3/$G$3 -> 97.692308 | I30: =CEILING(H30,0.5) -> 98
A31: =SUBTOTAL(3,$B$4:$B31)*1 -> 28 | B31: 62956 | C31: นางสาวปภาณิน ป้องบุญมี | D31: 60 | E31: 39 | F31: 30 | G31: =SUM(D31:F31) -> 129 | H31: =G31*$H$3/$G$3 -> 99.230769 | I31: =CEILING(H31,0.5) -> 99.5
A32: =SUBTOTAL(3,$B$4:$B32)*1 -> 29 | B32: 63093 | C32: นายพงศกร ปลอดโปร่ง | D32: 52 | E32: 39 | F32: 30 | G32: =SUM(D32:F32) -> 121 | H32: =G32*$H$3/$G$3 -> 93.076923 | I32: =CEILING(H32,0.5) -> 93.5
A33: =SUBTOTAL(3,$B$4:$B33)*1 -> 30 | B33: 63159 | C33: นายเกียรติศักดิ์ บุญหลง | D33: 56 | E33: 39 | F33: 30 | G33: =SUM(D33:F33) -> 125 | H33: =G33*$H$3/$G$3 -> 96.153846 | I33: =CEILING(H33,0.5) -> 96.5
A34: =SUBTOTAL(3,$B$4:$B34)*1 -> 31 | B34: 63248 | C34: นางสาววิไลพร สัมฤทธิ์ | D34: 56 | E34: 40 | F34: 30 | G34: =SUM(D34:F34) -> 126 | H34: =G34*$H$3/$G$3 -> 96.923077 | I34: =CEILING(H34,0.5) -> 97
A35: =SUBTOTAL(3,$B$4:$B35)*1 -> 32 | B35: 63249 | C35: นางสาวเวณิกา เสียมไหม | D35: 48/60 | E35: 38/40 | F35: 18/28 | G35: 104/128 | H35: =G35*$H$3/$G$3 -> #VALUE! | I35: 80/98.50 | J35: ซ่อมผ่าน
A36: =SUBTOTAL(3,$B$4:$B36)*1 -> 33 | B36: 63371 | C36: นางสาวนวพร บาลี | D36: 58 | E36: 39 | F36: 23 | G36: =SUM(D36:F36) -> 120 | H36: =G36*$H$3/$G$3 -> 92.307692 | I36: =CEILING(H36,0.5) -> 92.5
A37: =SUBTOTAL(3,$B$4:$B37)*1 -> 34 | B37: 63431 | C37: นางสาวณัฏฐ์ชญา สีสมุดคำ | D37: 56 | E37: 38 | F37: 30 | G37: =SUM(D37:F37) -> 124 | H37: =G37*$H$3/$G$3 -> 95.384615 | I37: =CEILING(H37,0.5) -> 95.5
A38: =SUBTOTAL(3,$B$4:$B38)*1 -> 35 | B38: 63433 | C38: นางสาวญาสมินทร์ ทับทอง | D38: 60 | E38: 38 | F38: 29 | G38: =SUM(D38:F38) -> 127 | H38: =G38*$H$3/$G$3 -> 97.692308 | I38: =CEILING(H38,0.5) -> 98
A39: =SUBTOTAL(3,$B$4:$B39)*1 -> 36 | B39: 63436 | C39: นางสาวณัฏฐ์นรี ตำหนักที่ | D39: 60 | E39: 39 | F39: 30 | G39: =SUM(D39:F39) -> 129 | H39: =G39*$H$3/$G$3 -> 99.230769 | I39: =CEILING(H39,0.5) -> 99.5
A40: =SUBTOTAL(3,$B$4:$B40)*1 -> 37 | B40: 63439 | C40: นางสาวอภิญญา พงศ์พูนทรัพย์ | D40: 60 | E40: 38 | F40: 30 | G40: =SUM(D40:F40) -> 128 | H40: =G40*$H$3/$G$3 -> 98.461538 | I40: =CEILING(H40,0.5) -> 98.5
...

Sheet สรุปผลครั้งที่ 1
B1: สรุปผลการสอบความรู้ในงาน ครั้งที่ 1 สังกัด KPD -DMK ประจำปี 2568
B2: พนักงานที่ทำแบบทดสอบความรู้ในงานทั้งหมด
B3: ระดับ | C3: จำนวนพนักงานทั้งหมด | D3: ผ่านเกณฑ์ 90% | H3: หมายเหตุ
D4: ผ่าน ( คน ) | E4: คิดเป็น % | F4: ซ่อมผ่าน ( คน ) | G4: คิดเป็น %
B5: 2C | C5: 19 | D5: 17 | E5: =D5/C5 -> 0.89473684 | F5: 2 | G5: =F5/C5 -> 0.10526316
B6: 1A , 1B | C6: 50 | D6: 42 | E6: =D6/C6 -> 0.84 | F6: 8 | G6: =F6/C6 -> 0.16
B7: รวม | C7: =SUM(C5:C6) -> 69 | D7: =SUM(D5:D6) -> 59 | E7: =D7/C7 -> 0.85507246 | F7: =SUM(F5:F6) -> 10 | G7: =F7/C7 -> 0.14492754
B9: พนักงานที่เข้าร่วมโครงการ
B10: ระดับ | C10: จำนวนพนักงานทั้งหมด | D10: เข้าร่วมโครงการ | E10: ผ่านเกณฑ์ 90% | I10: ไม่ร่วมโครงการ | J10: หมายเหตุ
E11: ผ่าน ( คน ) | F11: คิดเป็น % | G11: ซ่อมผ่าน ( คน ) | H11: คิดเป็น %
B12: 2C | C12: 19 | D12: 19 | E12: 17 | F12: =E12/D12 -> 0.89473684 | G12: 2 | H12: =G12/D12 -> 0.10526316 | I12: -
B13: 1A , 1B | C13: 50 | D13: 45 | E13: 39 | F13: =E13/D13 -> 0.86666667 | G13: 6 | H13: =G13/D13 -> 0.13333333 | I13: 5
B14: รวม | C14: =SUM(C12:C13) -> 69 | D14: =SUM(D12:D13) -> 64 | E14: =SUM(E12:E13) -> 56 | F14: =E14/D14 -> 0.875 | G14: =SUM(G12:G13) -> 8 | H14: =G14/D14 -> 0.125 | I14: =SUM(I12:I13) -> 5

Sheet 2C 2B ครั้งที่ 2
A1: ตารางบันทึกคะแนน สอบความรู้ในงาน SUPERVISOR 2B,2B ครั้งที่ 2 /2568
A2: ลำดับ | B2: ID | C2: ชื่อ - สกุล | D2: ISO | E2: ความรู้ทั่วไป | F2: CASH | G2: GRAND TOTAL | H2: TOTAL | I2: TOTAL | J2: หมายเหตุ | L2: ISO | M2: ความรู้ทั่วไป | N2: CASH | O2: GRAND TOTAL
D3: 60 | E3: 40 | F3: 30 | G3: =SUM(D3:F3) -> 130 | H3: 100 | I3: 100 | L3: =(90*60)/100 -> 54 | M3: =(90*40)/100 -> 36 | N3: =(90*30)/100 -> 27 | O3: =(90*130)/100 -> 117
A4: 1 | B4: 1730 | C4: นางอมร ทฤษฎี | D4: 60 | E4: 36 | F4: 28 | G4: =SUM(D4:F4) -> 124 | H4: =G4*$H$3/$G$3 -> 95.384615 | I4: =CEILING(H4,0.5) -> 95.5
A5: 2 | B5: 5540 | C5: นางสาวกนิษฐา ศรีอาภัย | D5: 60 | E5: 39 | F5: 28 | G5: =SUM(D5:F5) -> 127 | H5: =G5*$H$3/$G$3 -> 97.692308 | I5: =CEILING(H5,0.5) -> 98
A6: 3 | B6: 9038 | C6: นางสาวทสพร ทองทา | D6: 60 | E6: 37 | F6: 29 | G6: =SUM(D6:F6) -> 126 | H6: =G6*$H$3/$G$3 -> 96.923077 | I6: =CEILING(H6,0.5) -> 97
A7: 4 | B7: 12324 | C7: นางสาวสุรัสสา ผาสุข | D7: 60 | E7: 37 | F7: 30 | G7: =SUM(D7:F7) -> 127 | H7: =G7*$H$3/$G$3 -> 97.692308 | I7: =CEILING(H7,0.5) -> 98
A8: 5 | B8: 18512 | C8: นางสาวจุติพร สุญาสิทธิ์ | D8: 58 | E8: 37 | F8: 30 | G8: =SUM(D8:F8) -> 125 | H8: =G8*$H$3/$G$3 -> 96.153846 | I8: =CEILING(H8,0.5) -> 96.5
A10: =SUBTOTAL(3,$B$10:$B10)*1 -> 1 | B10: 3643 | C10: นางกัญญาภัค ศุภมนตรี | F10: 28 | G10: =SUM(D10:F10) -> 28 | H10: =G10*$H$3/$G$3 -> 21.538462 | I10: =CEILING(H10,0.5) -> 22
A11: =SUBTOTAL(3,$B$10:$B11)*1 -> 2 | B11: 4843 | C11: นางสาวรุ่งเรือง หงษ์ลอย | D11: 60 | E11: 40 | F11: 30 | G11: =SUM(D11:F11) -> 130 | H11: =G11*$H$3/$G$3 -> 100 | I11: =CEILING(H11,0.5) -> 100
A12: =SUBTOTAL(3,$B$10:$B12)*1 -> 3 | B12: 5209 | C12: นางสาวจิราภรณ์ ทองบุญ | D12: 60 | E12: 38 | F12: 29 | G12: =SUM(D12:F12) -> 127 | H12: =G12*$H$3/$G$3 -> 97.692308 | I12: =CEILING(H12,0.5) -> 98
A13: =SUBTOTAL(3,$B$10:$B13)*1 -> 4 | B13: 5258 | C13: นางปรียาภรณ์ ขำสงค์ชัยเจริญ | F13: 28 | G13: =SUM(D13:F13) -> 28 | H13: =G13*$H$3/$G$3 -> 21.538462 | I13: =CEILING(H13,0.5) -> 22
A14: =SUBTOTAL(3,$B$10:$B14)*1 -> 5 | B14: 7898 | C14: นางสาวศรัณยา ลีละภมรกิจ | D14: 60 | E14: 39 | F14: 28 | G14: =SUM(D14:F14) -> 127 | H14: =G14*$H$3/$G$3 -> 97.692308 | I14: =CEILING(H14,0.5) -> 98
A15: =SUBTOTAL(3,$B$10:$B15)*1 -> 6 | B15: 11467 | C15: นางสาวกรรณิกา มีมุข | D15: 60 | E15: 40 | F15: 30 | G15: =SUM(D15:F15) -> 130 | H15: =G15*$H$3/$G$3 -> 100 | I15: =CEILING(H15,0.5) -> 100
A16: =SUBTOTAL(3,$B$10:$B16)*1 -> 7 | B16: 12047 | C16: นางสาวอัญชลี ปั้นแตง | D16: 60 | E16: 39 | F16: 30 | G16: =SUM(D16:F16) -> 129 | H16: =G16*$H$3/$G$3 -> 99.230769 | I16: =CEILING(H16,0.5) -> 99.5
A17: =SUBTOTAL(3,$B$10:$B17)*1 -> 8 | B17: 12259 | C17: นางสาวมนธิชา จันทะผล | D17: 60 | E17: 40 | F17: 29 | G17: =SUM(D17:F17) -> 129 | H17: =G17*$H$3/$G$3 -> 99.230769 | I17: =CEILING(H17,0.5) -> 99.5
A18: =SUBTOTAL(3,$B$10:$B18)*1 -> 9 | B18: 17151 | C18: นางสาวภัทรณัฏฐ์ ขจรพัชรสกุล | F18: 29 | G18: =SUM(D18:F18) -> 29 | H18: =G18*$H$3/$G$3 -> 22.307692 | I18: =CEILING(H18,0.5) -> 22.5
A19: =SUBTOTAL(3,$B$10:$B19)*1 -> 10 | B19: 19197 | C19: นางสาวเกตุวดี จูเกตุ | D19: 58 | E19: 39 | F19: 30 | G19: =SUM(D19:F19) -> 127 | H19: =G19*$H$3/$G$3 -> 97.692308 | I19: =CEILING(H19,0.5) -> 98
A20: =SUBTOTAL(3,$B$10:$B20)*1 -> 11 | B20: 25647 | C20: นางสาวรุ่งรัตน์ ดาวไธสง | D20: 60 | E20: 40 | F20: 30 | G20: =SUM(D20:F20) -> 130 | H20: =G20*$H$3/$G$3 -> 100 | I20: =CEILING(H20,0.5) -> 100
A21: =SUBTOTAL(3,$B$10:$B21)*1 -> 12 | B21: 33577 | C21: นางสาวอรสุรางค์ ภาคบูรณ์ | D21: 60 | E21: 40 | F21: 28 | G21: =SUM(D21:F21) -> 128 | H21: =G21*$H$3/$G$3 -> 98.461538 | I21: =CEILING(H21,0.5) -> 98.5
A22: =SUBTOTAL(3,$B$10:$B22)*1 -> 13 | B22: 32901 | C22: นางสาวประภาพร มากเจริญ | F22: 30 | G22: =SUM(D22:F22) -> 30 | H22: =G22*$H$3/$G$3 -> 23.076923 | I22: =CEILING(H22,0.5) -> 23.5
A23: =SUBTOTAL(3,$B$10:$B23)*1 -> 14 | B23: 35911 | C23: นางสาวพิชญ์ชิชา หาญธีรวิรสร์ | D23: 60 | E23: 40 | F23: 30 | G23: =SUM(D23:F23) -> 130 | H23: =G23*$H$3/$G$3 -> 100 | I23: =CEILING(H23,0.5) -> 100
A24: =SUBTOTAL(3,$B$10:$B24)*1 -> 15 | B24: 62885 | C24: นางสาวศุภวรรณ แดงทอง | D24: 60 | E24: 39 | F24: 28 | G24: =SUM(D24:F24) -> 127 | H24: =G24*$H$3/$G$3 -> 97.692308 | I24: =CEILING(H24,0.5) -> 98
A25: =SUBTOTAL(3,$B$10:$B25)*1 -> 16 | B25: 37439 | C25: นางสาวนภัสวรรณ ชะฎาจิตร | D25: 60 | E25: 40 | F25: 28 | G25: =SUM(D25:F25) -> 128 | H25: =G25*$H$3/$G$3 -> 98.461538 | I25: =CEILING(H25,0.5) -> 98.5
A26: =SUBTOTAL(3,$B$10:$B26)*1 -> 17 | B26: 37441 | C26: นางสาวกัญศิธณุวัน กาญจน์ศิฐกุล | D26: 60 | E26: 40 | F26: 30 | G26: =SUM(D26:F26) -> 130 | H26: =G26*$H$3/$G$3 -> 100 | I26: =CEILING(H26,0.5) -> 100

Sheet 1B 1A ครั้งที่ 2
A1: ตารางบันทึกคะแนน สอบความรู้ในงาน CASHIER 1B 1A ครั้งที่ 2 /2568
A2: ลำดับ | B2: ID | C2: ชื่อ - สกุล | D2: ISO | E2: ความรู้ทั่วไป | F2: CASH | G2: GRAND TOTAL | H2: TOTAL | I2: TOTAL | J2: หมายเหตุ | K2: ไม่ร่วมโครงการ | N2: ISO | O2: ความรู้ทั่วไป | P2: CASH | Q2: GRAND TOTAL
D3: 60 | E3: 40 | F3: 30 | G3: =SUM(D3:F3) -> 130 | H3: 100 | I3: 100 | N3: =(90*60)/100 -> 54 | O3: =(90*40)/100 -> 36 | P3: =(90*30)/100 -> 27 | Q3: =(90*130)/100 -> 117
A4: =SUBTOTAL(3,$B$4:$B4)*1 -> 1 | B4: 2117 | C4: นางสาวบุญจิรา ไสยยา | G4: =SUM(D4:F4) -> 0 | H4: =G4*$H$3/$G$3 -> 0 | I4: =CEILING(H4,0.5) -> 0
A5: =SUBTOTAL(3,$B$4:$B5)*1 -> 2 | B5: 22954 | C5: นางสาวกาญจนา ถาวรวัน | G5: =SUM(D5:F5) -> 0 | H5: =G5*$H$3/$G$3 -> 0 | I5: =CEILING(H5,0.5) -> 0
A6: =SUBTOTAL(3,$B$4:$B6)*1 -> 3 | B6: 34500 | C6: นางสาวนิศารัตน์ นาสันเทียะ | G6: =SUM(D6:F6) -> 0 | H6: =G6*$H$3/$G$3 -> 0 | I6: =CEILING(H6,0.5) -> 0
A7: =SUBTOTAL(3,$B$4:$B7)*1 -> 4 | B7: 35518 | C7: นางวราพรรณ คงธน | G7: =SUM(D7:F7) -> 0 | H7: =G7*$H$3/$G$3 -> 0 | I7: =CEILING(H7,0.5) -> 0
A8: =SUBTOTAL(3,$B$4:$B8)*1 -> 5 | B8: 35528 | C8: นางสาวศุภลักษณ์ วงษ์ชาชม | G8: =SUM(D8:F8) -> 0 | H8: =G8*$H$3/$G$3 -> 0 | I8: =CEILING(H8,0.5) -> 0
A9: =SUBTOTAL(3,$B$4:$B9)*1 -> 6 | B9: 38834 | C9: นางสาวสุภาวดี เอี่ยมอารยกุล | G9: =SUM(D9:F9) -> 0 | H9: =G9*$H$3/$G$3 -> 0 | I9: =CEILING(H9,0.5) -> 0
A10: =SUBTOTAL(3,$B$4:$B10)*1 -> 7 | B10: 60869 | C10: นางสาวธัญญรัตน์ นาคำ | G10: =SUM(D10:F10) -> 0 | H10: =G10*$H$3/$G$3 -> 0 | I10: =CEILING(H10,0.5) -> 0
A11: =SUBTOTAL(3,$B$4:$B11)*1 -> 8 | B11: 60886 | C11: นางสาวการสดา สังฆะศรี | G11: =SUM(D11:F11) -> 0 | H11: =G11*$H$3/$G$3 -> 0 | I11: =CEILING(H11,0.5) -> 0
A12: =SUBTOTAL(3,$B$4:$B12)*1 -> 9 | B12: 60890 | C12: นางสาวกัญญาพัชร เสาะแสวง | G12: =SUM(D12:F12) -> 0 | H12: =G12*$H$3/$G$3 -> 0 | I12: =CEILING(H12,0.5) -> 0
A13: =SUBTOTAL(3,$B$4:$B13)*1 -> 10 | B13: 61826 | C13: นางสาวปาริชาติ จันทร์ขาว | G13: =SUM(D13:F13) -> 0 | H13: =G13*$H$3/$G$3 -> 0 | I13: =CEILING(H13,0.5) -> 0
A14: =SUBTOTAL(3,$B$4:$B14)*1 -> 11 | B14: 62442 | C14: นายธัญวุฒิ สมยันพล | G14: =SUM(D14:F14) -> 0 | H14: =G14*$H$3/$G$3 -> 0 | I14: =CEILING(H14,0.5) -> 0
A15: =SUBTOTAL(3,$B$4:$B15)*1 -> 12 | B15: 62559 | C15: นางสาวกมลทิพย์ อาจกลาง | G15: =SUM(D15:F15) -> 0 | H15: =G15*$H$3/$G$3 -> 0 | I15: =CEILING(H15,0.5) -> 0
... A25: =SUBTOTAL(3,$B$4:$B25)*1 -> 22 | B25: 63159 | C25: นายเกียรติศักดิ์ บุญหลง | G25: =SUM(D25:F25) -> 0 | H25: =G25*$H$3/$G$3 -> 0 | I25: =CEILING(H25,0.5) -> 0
A26: =SUBTOTAL(3,$B$4:$B26)*1 -> 23 | B26: 63248 | C26: นางสาววิไลพร สัมฤทธิ์ | G26: =SUM(D26:F26) -> 0 | H26: =G26*$H$3/$G$3 -> 0 | I26: =CEILING(H26,0.5) -> 0 | K26: ลาคลอด
A27: =SUBTOTAL(3,$B$4:$B27)*1 -> 24 | B27: 63249 | C27: นางสาวเวณิกา เสียมไหม | G27: =SUM(D27:F27) -> 0 | H27: =G27*$H$3/$G$3 -> 0 | I27: =CEILING(H27,0.5) -> 0
A28: =SUBTOTAL(3,$B$4:$B28)*1 -> 25 | B28: 63371 | C28: นางสาวนวพร บาลี | G28: =SUM(D28:F28) -> 0 | H28: =G28*$H$3/$G$3 -> 0 | I28: =CEILING(H28,0.5) -> 0
A29: =SUBTOTAL(3,$B$4:$B29)*1 -> 26 | B29: 63431 | C29: นางสาวณัฏฐ์ชญา สีสมุดคำ | G29: =SUM(D29:F29) -> 0 | H29: =G29*$H$3/$G$3 -> 0 | I29: =CEILING(H29,0.5) -> 0
A30: =SUBTOTAL(3,$B$4:$B30)*1 -> 27 | B30: 63433 | C30: นางสาวญาสมินทร์ ทับทอง | G30: =SUM(D30:F30) -> 0 | H30: =G30*$H$3/$G$3 -> 0 | I30: =CEILING(H30,0.5) -> 0
A31: =SUBTOTAL(3,$B$4:$B31)*1 -> 28 | B31: 63436 | C31: นางสาวณัฏฐ์นรี ตำหนักที่ | G31: =SUM(D31:F31) -> 0 | H31: =G31*$H$3/$G$3 -> 0 | I31: =CEILING(H31,0.5) -> 0
A32: =SUBTOTAL(3,$B$4:$B32)*1 -> 29 | B32: 63439 | C32: นางสาวอภิญญา พงศ์พูนทรัพย์ | G32: =SUM(D32:F32) -> 0 | H32: =G32*$H$3/$G$3 -> 0 | I32: =CEILING(H32,0.5) -> 0
A33: =SUBTOTAL(3,$B$4:$B33)*1 -> 30 | B33: 63550 | C33: นางสาวกชกร ไขว้เครือ | G33: =SUM(D33:F33) -> 0 | H33: =G33*$H$3/$G$3 -> 0 | I33: =CEILING(H33,0.5) -> 0
A34: =SUBTOTAL(3,$B$4:$B34)*1 -> 31 | B34: 63564 | C34: นางสาวสินีนาถ สงวนศรี | G34: =SUM(D34:F34) -> 0 | H34: =G34*$H$3/$G$3 -> 0 | I34: =CEILING(H34,0.5) -> 0 | K34: ลาคลอด
A35: =SUBTOTAL(3,$B$4:$B35)*1 -> 32 | B35: 63567 | C35: นางสาวสุจิตรา ภูพันนา | G35: =SUM(D35:F35) -> 0 | H35: =G35*$H$3/$G$3 -> 0 | I35: =CEILING(H35,0.5) -> 0
A36: =SUBTOTAL(3,$B$4:$B36)*1 -> 33 | B36: 63652 | C36: นางสาวสุดารัตน์ คูณศรี | G36: =SUM(D36:F36) -> 0 | H36: =G36*$H$3/$G$3 -> 0 | I36: =CEILING(H36,0.5) -> 0
A37: =SUBTOTAL(3,$B$4:$B37)*1 -> 34 | B37: 63658 | C37: นางสาวนัฐรดี เสนาปัก | G37: =SUM(D37:F37) -> 0 | H37: =G37*$H$3/$G$3 -> 0 | I37: =CEILING(H37,0.5) -> 0
A38: =SUBTOTAL(3,$B$4:$B38)*1 -> 35 | B38: 64312 | C38: นางสาวมินตรา เครือมาศ | G38: =SUM(D38:F38) -> 0 | H38: =G38*$H$3/$G$3 -> 0 | I38: =CEILING(H38,0.5) -> 0 | K38: อายุงานไม่ถึง 1 ปี
A39: =SUBTOTAL(3,$B$4:$B39)*1 -> 36 | B39: 64313 | C39: นางสาวภัทชนก จิตรประสงค์ | G39: =SUM(D39:F39) -> 0 | H39: =G39*$H$3/$G$3 -> 0 | I39: =CEILING(H39,0.5) -> 0 | K39: อายุงานไม่ถึง 1 ปี
A40: =SUBTOTAL(3,$B$4:$B40)*1 -> 37 | B40: 64355 | C40: นางสาวพิมลพรรณ สังข์ทอง | G40: =SUM(D40:F40) -> 0 | H40: =G40*$H$3/$G$3 -> 0 | I40: =CEILING(H40,0.5) -> 0 | K40: อายุงานไม่ถึง 1 ปี

Sheet สรุปผลครั้งที่ 2
B1: สรุปผลการสอบความรู้ในงาน ครั้งที่ 2 สังกัด KPD -DMK ประจำปี 2568
B2: พนักงานที่ทำแบบทดสอบความรู้ในงานทั้งหมด
B3: ระดับ | C3: จำนวนพนักงานทั้งหมด | D3: ผ่านเกณฑ์ 90% | H3: หมายเหตุ
D4: ผ่าน ( คน ) | E4: คิดเป็น % | F4: ซ่อมผ่าน ( คน ) | G4: คิดเป็น %
B5: 2C | C5: 17 | E5: =D5/C5 -> 0 | G5: =F5/C5 -> 0
B6: 1A , 1B | C6: 37 | E6: =D6/C6 -> 0 | G6: =F6/C6 -> 0
B7: รวม | C7: =SUM(C5:C6) -> 54 | D7: =SUM(D5:D6) -> 0 | E7: =D7/C7 -> 0 | F7: =SUM(F5:F6) -> 0 | G7: =F7/C7 -> 0
B9: พนักงานที่เข้าร่วมโครงการ
B10: ระดับ | C10: จำนวนพนักงานทั้งหมด | D10: เข้าร่วมโครงการ | E10: ผ่านเกณฑ์ 90% | I10: ไม่ร่วมโครงการ | J10: หมายเหตุ
E11: ผ่าน ( คน ) | F11: คิดเป็น % | G11: ซ่อมผ่าน ( คน ) | H11: คิดเป็น %
B12: 2C | C12: 17 | D12: 17 | F12: =E12/D12 -> 0 | H12: =G12/D12 -> 0 | I12: -
B13: 1A , 1B | C13: 37 | D13: 33 | F13: =E13/D13 -> 0 | H13: =G13/D13 -> 0 | I13: 4
B14: รวม | C14: =SUM(C12:C13) -> 54 | D14: =SUM(D12:D13) -> 50 | E14: =SUM(E12:E13) -> 0 | F14: =E14/D14 -> 0 | G14: =SUM(G12:G13) -> 0 | H14: =G14/D14 -> 0 | I14: =SUM(I12:I13) -> 4

Sheet 2C 2B คะแนนตามเกณฑ์
A1: ตารางบันทึกคะแนน แผนงาน ELITE TEAM 2568 SUPERVISOR 2C 2B
A2: ลำดับ | B2: ID | C2: ชื่อ - สกุล | D2: ความรู้ในงาน+ทักษะ | G2: จำนวนวันที่ | H2: คำชมเชย | I2: ปริมาณ | J2: ความผิดพลาดที่มีผล | K2: จำนวนรายการขาย | L2: TOTAL | M2: สรุปผล | N2: หมายเหตุ
D3: ครั้งที่ 1 | E3: ครั้งที่ 2 | F3: รวม | G3: มาปฏิบัติงาน | I3: งาน | J3: กระทบกับลูกค้า | K3: พนักงานทำได้
F4: 30 | G4: 15 | H4: 10 | I4: 15 | J4: 20 | K4: 10 | L4: =SUM(F4:K4) -> 100
A5: 1 | B5: 1730 | C5: นางอมร ทฤษฎี | D5: =VLOOKUP(B5,'2C 2B ครั้งที่ 1'!$B$4:$I$28,8,0) -> 89.5 | E5: =VLOOKUP(B5,'2C 2B ครั้งที่ 2'!$B$4:$I$26,8,0) -> 95.5 | F5: =AVERAGE(D5:E5) -> 92.5
A6: 2 | B6: 5540 | C6: นางสาวกนิษฐา ศรีอาภัย | D6: =VLOOKUP(B6,'2C 2B ครั้งที่ 1'!$B$4:$I$28,8,0) -> 98 | E6: =VLOOKUP(B6,'2C 2B ครั้งที่ 2'!$B$4:$I$26,8,0) -> 98 | F6: =AVERAGE(D6:E6) -> 98
A7: 3 | B7: 9038 | C7: นางสาวทสพร ทองทา | D7: =VLOOKUP(B7,'2C 2B ครั้งที่ 1'!$B$4:$I$28,8,0) -> 98.5 | E7: =VLOOKUP(B7,'2C 2B ครั้งที่ 2'!$B$4:$I$26,8,0) -> 97 | F7: =AVERAGE(D7:E7) -> 97.75
A8: 4 | B8: 12324 | C8: นางสาวสุรัสสา ผาสุข | D8: =VLOOKUP(B8,'2C 2B ครั้งที่ 1'!$B$4:$I$28,8,0) -> 94 | E8: =VLOOKUP(B8,'2C 2B ครั้งที่ 2'!$B$4:$I$26,8,0) -> 98 | F8: =AVERAGE(D8:E8) -> 96
A9: 5 | B9: 18512 | C9: นางสาวจุติพร สุญาสิทธิ์ | D9: =VLOOKUP(B9,'2C 2B ครั้งที่ 1'!$B$4:$I$28,8,0) -> 95.5 | E9: =VLOOKUP(B9,'2C 2B ครั้งที่ 2'!$B$4:$I$26,8,0) -> 96.5 | F9: =AVERAGE(D9:E9) -> 96
A11: =SUBTOTAL(3,$B$11:$B11)*1 -> 1 | B11: 3643 | C11: นางกัญญาภัค ศุภมนตรี | D11: =VLOOKUP(B11,'2C 2B ครั้งที่ 1'!$B$4:$I$28,8,0) -> 93.5 | E11: =VLOOKUP(B11,'2C 2B ครั้งที่ 2'!$B$4:$I$26,8,0) -> 22 | F11: =AVERAGE(D11:E11) -> 57.75
A12: =SUBTOTAL(3,$B$11:$B12)*1 -> 2 | B12: 4843 | C12: นางสาวรุ่งเรือง หงษ์ลอย | D12: =VLOOKUP(B12,'2C 2B ครั้งที่ 1'!$B$4:$I$28,8,0) -> 92.5 | E12: =VLOOKUP(B12,'2C 2B ครั้งที่ 2'!$B$4:$I$26,8,0) -> 100 | F12: =AVERAGE(D12:E12) -> 96.25
A13: =SUBTOTAL(3,$B$11:$B13)*1 -> 3 | B13: 5209 | C13: นางสาวจิราภรณ์ ทองบุญ | D13: =VLOOKUP(B13,'2C 2B ครั้งที่ 1'!$B$4:$I$28,8,0) -> 96.5 | E13: =VLOOKUP(B13,'2C 2B ครั้งที่ 2'!$B$4:$I$26,8,0) -> 98 | F13: =AVERAGE(D13:E13) -> 97.25
A14: =SUBTOTAL(3,$B$11:$B14)*1 -> 4 | B14: 5258 | C14: นางปรียาภรณ์ ขำสงค์ชัยเจริญ | D14: =VLOOKUP(B14,'2C 2B ครั้งที่ 1'!$B$4:$I$28,8,0) -> 95 | E14: =VLOOKUP(B14,'2C 2B ครั้งที่ 2'!$B$4:$I$26,8,0) -> 22 | F14: =AVERAGE(D14:E14) -> 58.5
A15: =SUBTOTAL(3,$B$11:$B15)*1 -> 5 | B15: 7898 | C15: นางสาวศรัณยา ลีละภมรกิจ | D15: =VLOOKUP(B15,'2C 2B ครั้งที่ 1'!$B$4:$I$28,8,0) -> 90 | E15: =VLOOKUP(B15,'2C 2B ครั้งที่ 2'!$B$4:$I$26,8,0) -> 98 | F15: =AVERAGE(D15:E15) -> 94
A16: =SUBTOTAL(3,$B$11:$B16)*1 -> 6 | B16: 11467 | C16: นางสาวกรรณิกา มีมุข | D16: =VLOOKUP(B16,'2C 2B ครั้งที่ 1'!$B$4:$I$28,8,0) -> 99.5 | E16: =VLOOKUP(B16,'2C 2B ครั้งที่ 2'!$B$4:$I$26,8,0) -> 100 | F16: =AVERAGE(D16:E16) -> 99.75
A17: =SUBTOTAL(3,$B$11:$B17)*1 -> 7 | B17: 12047 | C17: นางสาวอัญชลี ปั้นแตง | D17: =VLOOKUP(B17,'2C 2B ครั้งที่ 1'!$B$4:$I$28,8,0) -> 95.5 | E17: =VLOOKUP(B17,'2C 2B ครั้งที่ 2'!$B$4:$I$26,8,0) -> 99.5 | F17: =AVERAGE(D17:E17) -> 97.5
A18: =SUBTOTAL(3,$B$11:$B18)*1 -> 8 | B18: 12259 | C18: นางสาวมนธิชา จันทะผล | D18: =VLOOKUP(B18,'2C 2B ครั้งที่ 1'!$B$4:$I$28,8,0) -> 100 | E18: =VLOOKUP(B18,'2C 2B ครั้งที่ 2'!$B$4:$I$26,8,0) -> 99.5 | F18: =AVERAGE(D18:E18) -> 99.75 | N18: ซ่อมผ่าน
A19: =SUBTOTAL(3,$B$11:$B19)*1 -> 9 | B19: 17151 | C19: นางสาวภัทรณัฏฐ์ ขจรพัชรสกุล | D19: =VLOOKUP(B19,'2C 2B ครั้งที่ 1'!$B$4:$I$28,8,0) -> 92 | E19: =VLOOKUP(B19,'2C 2B ครั้งที่ 2'!$B$4:$I$26,8,0) -> 22.5 | F19: =AVERAGE(D19:E19) -> 57.25
A20: =SUBTOTAL(3,$B$11:$B20)*1 -> 10 | B20: 19197 | C20: นางสาวเกตุวดี จูเกตุ | D20: =VLOOKUP(B20,'2C 2B ครั้งที่ 1'!$B$4:$I$28,8,0) -> 95 | E20: =VLOOKUP(B20,'2C 2B ครั้งที่ 2'!$B$4:$I$26,8,0) -> 98 | F20: =AVERAGE(D20:E20) -> 96.5
A21: =SUBTOTAL(3,$B$11:$B21)*1 -> 11 | B21: 25647 | C21: นางสาวรุ่งรัตน์ ดาวไธสง | D21: =VLOOKUP(B21,'2C 2B ครั้งที่ 1'!$B$4:$I$28,8,0) -> 92 | E21: =VLOOKUP(B21,'2C 2B ครั้งที่ 2'!$B$4:$I$26,8,0) -> 100 | F21: =AVERAGE(D21:E21) -> 96
A22: =SUBTOTAL(3,$B$11:$B22)*1 -> 12 | B22: 33577 | C22: นางสาวอรสุรางค์ ภาคบูรณ์ | D22: =VLOOKUP(B22,'2C 2B ครั้งที่ 1'!$B$4:$I$28,8,0) -> 98 | E22: =VLOOKUP(B22,'2C 2B ครั้งที่ 2'!$B$4:$I$26,8,0) -> 98.5 | F22: =AVERAGE(D22:E22) -> 98.25
A23: =SUBTOTAL(3,$B$11:$B23)*1 -> 13 | B23: 32901 | C23: นางสาวประภาพร มากเจริญ | D23: =VLOOKUP(B23,'2C 2B ครั้งที่ 1'!$B$4:$I$28,8,0) -> 96.5 | E23: =VLOOKUP(B23,'2C 2B ครั้งที่ 2'!$B$4:$I$26,8,0) -> 23.5 | F23: =AVERAGE(D23:E23) -> 60
A24: =SUBTOTAL(3,$B$11:$B24)*1 -> 14 | B24: 35911 | C24: นางสาวพิชญ์ชิชา หาญธีรวิรสร์ | D24: =VLOOKUP(B24,'2C 2B ครั้งที่ 1'!$B$4:$I$28,8,0) -> 95 | E24: =VLOOKUP(B24,'2C 2B ครั้งที่ 2'!$B$4:$I$26,8,0) -> 100 | F24: =AVERAGE(D24:E24) -> 97.5
A25: =SUBTOTAL(3,$B$11:$B25)*1 -> 15 | B25: 62885 | C25: นางสาวศุภวรรณ แดงทอง | D25: =VLOOKUP(B25,'2C 2B ครั้งที่ 1'!$B$4:$I$28,8,0) -> 98 | E25: =VLOOKUP(B25,'2C 2B ครั้งที่ 2'!$B$4:$I$26,8,0) -> 98 | F25: =AVERAGE(D25:E25) -> 98
A26: =SUBTOTAL(3,$B$11:$B26)*1 -> 16 | B26: 37439 | C26: นางสาวนภัสวรรณ ชะฎาจิตร | D26: =VLOOKUP(B26,'2C 2B ครั้งที่ 1'!$B$4:$I$28,8,0) -> 98.5 | E26: =VLOOKUP(B26,'2C 2B ครั้งที่ 2'!$B$4:$I$26,8,0) -> 98.5 | F26: =AVERAGE(D26:E26) -> 98.5
A27: =SUBTOTAL(3,$B$11:$B27)*1 -> 17 | B27: 37441 | C27: นางสาวกัญศิธณุวัน กาญจน์ศิฐกุล | D27: =VLOOKUP(B27,'2C 2B ครั้งที่ 1'!$B$4:$I$28,8,0) -> 98.5 | E27: =VLOOKUP(B27,'2C 2B ครั้งที่ 2'!$B$4:$I$26,8,0) -> 100 | F27: =AVERAGE(D27:E27) -> 99.25

Sheet 1B 1A คะแนนตามเกณฑ์
A1: ตารางบันทึกคะแนน แผนงาน ELITE TEAM 2568 CASHIER 1B 1A
A2: ลำดับ | B2: ID | C2: ชื่อ - สกุล | D2: ความรู้ในงาน+ทักษะ | G2: จำนวนวันที่ | H2: คำชมเชย | I2: ปริมาณ | J2: ความผิดพลาดที่มีผล | K2: จำนวนรายการขาย | L2: TOTAL | M2: สรุปผล | N2: หมายเหตุ
D3: ครั้งที่ 1 | E3: ครั้งที่ 2 | F3: รวม | G3: มาปฏิบัติงาน | I3: งาน | J3: กระทบกับลูกค้า | K3: พนักงานทำได้
F4: 30 | G4: 15 | H4: 10 | I4: 15 | J4: 20 | K4: 10 | L4: =SUM(F4:K4) -> 100
A5: =SUBTOTAL(3,$B$5:$B5)*1 -> 1 | B5: 2117 | C5: นางสาวบุญจิรา ไสยยา | D5: 98.5
A6: =SUBTOTAL(3,$B$5:$B6)*1 -> 2 | B6: 22954 | C6: นางสาวกาญจนา ถาวรวัน | D6: 98.5
A7: =SUBTOTAL(3,$B$5:$B7)*1 -> 3 | B7: 34500 | C7: นางสาวนิศารัตน์ นาสันเทียะ | D7: 99.5
A8: =SUBTOTAL(3,$B$5:$B8)*1 -> 4 | B8: 35518 | C8: นางวราพรรณ คงธน | D8: 93.5
A9: =SUBTOTAL(3,$B$5:$B9)*1 -> 5 | B9: 35528 | C9: นางสาวศุภลักษณ์ วงษ์ชาชม | D9: 98.5
A10: =SUBTOTAL(3,$B$5:$B10)*1 -> 6 | B10: 38834 | C10: นางสาวสุภาวดี เอี่ยมอารยกุล | D10: 100
A11: =SUBTOTAL(3,$B$5:$B11)*1 -> 7 | B11: 60869 | C11: นางสาวธัญญรัตน์ นาคำ | D11: 96.5
A12: =SUBTOTAL(3,$B$5:$B12)*1 -> 8 | B12: 60886 | C12: นางสาวการสดา สังฆะศรี | D12: 85/97 | N12: =VLOOKUP(B12,'1B 1A ครั้งที่ 1'!$B$4:$J$53,9,0) -> ซ่อมผ่าน
A13: =SUBTOTAL(3,$B$5:$B13)*1 -> 9 | B13: 60890 | C13: นางสาวกัญญาพัชร เสาะแสวง | D13: 97
A14: =SUBTOTAL(3,$B$5:$B14)*1 -> 10 | B14: 61826 | C14: นางสาวปาริชาติ จันทร์ขาว | D14: 100
A15: =SUBTOTAL(3,$B$5:$B15)*1 -> 11 | B15: 62442 | C15: นายธัญวุฒิ สมยันพล | D15: 98
A16: =SUBTOTAL(3,$B$5:$B16)*1 -> 12 | B16: 62559 | C16: นางสาวกมลทิพย์ อาจกลาง | D16: 98
A17: =SUBTOTAL(3,$B$5:$B17)*1 -> 13 | B17: 62679 | C17: นางสาววิชุดา ตีบจันทร์ | D17: 98.5
A18: =SUBTOTAL(3,$B$5:$B18)*1 -> 14 | B18: 62681 | C18: นางสาววรัญญา ปันแปง | D18: 80/97 | N18: =VLOOKUP(B18,'1B 1A ครั้งที่ 1'!$B$4:$J$53,9,0) -> ซ่อมผ่าน
A19: =SUBTOTAL(3,$B$5:$B19)*1 -> 15 | B19: 62736 | C19: นางสาววิภาดา ชูรัตน์ | D19: 98
A20: =SUBTOTAL(3,$B$5:$B20)*1 -> 16 | B20: 62810 | C20: นางสาวพลอยไพลิน เวทนา | D20: 99.5
A21: =SUBTOTAL(3,$B$5:$B21)*1 -> 17 | B21: 62882 | C21: นางสาวสุนิศา มูลชัย | D21: 97
A22: =SUBTOTAL(3,$B$5:$B22)*1 -> 18 | B22: 62952 | C22: นางสาวรัฐติกาล จิตต์พรหม | D22: 98.5
A23: =SUBTOTAL(3,$B$5:$B23)*1 -> 19 | B23: 62954 | C23: นางสาวปานชนก สุขโข | D23: 98
A24: =SUBTOTAL(3,$B$5:$B24)*1 -> 20 | B24: 62956 | C24: นางสาวปภาณิน ป้องบุญมี | D24: 99.5
A25: =SUBTOTAL(3,$B$5:$B25)*1 -> 21 | B25: 63093 | C25: นายพงศกร ปลอดโปร่ง | D25: 93.5
A26: =SUBTOTAL(3,$B$5:$B26)*1 -> 22 | B26: 63159 | C26: นายเกียรติศักดิ์ บุญหลง | D26: 96.5
A27: =SUBTOTAL(3,$B$5:$B27)*1 -> 23 | B27: 63248 | C27: นางสาววิไลพร สัมฤทธิ์ | D27: 97
A28: =SUBTOTAL(3,$B$5:$B28)*1 -> 24 | B28: 63249 | C28: นางสาวเวณิกา เสียมไหม | D28: 80/98.50 | N28: =VLOOKUP(B28,'1B 1A ครั้งที่ 1'!$B$4:$J$53,9,0) -> ซ่อมผ่าน
A29: =SUBTOTAL(3,$B$5:$B29)*1 -> 25 | B29: 63371 | C29: นางสาวนวพร บาลี | D29: 92.5
A30: =SUBTOTAL(3,$B$5:$B30)*1 -> 26 | B30: 63431 | C30: นางสาวณัฏฐ์ชญา สีสมุดคำ | D30: 95.5
A31: =SUBTOTAL(3,$B$5:$B31)*1 -> 27 | B31: 63433 | C31: นางสาวญาสมินทร์ ทับทอง | D31: 98
A32: =SUBTOTAL(3,$B$5:$B32)*1 -> 28 | B32: 63436 | C32: นางสาวณัฏฐ์นรี ตำหนักที่ | D32: 99.5
A33: =SUBTOTAL(3,$B$5:$B33)*1 -> 29 | B33: 63439 | C33: นางสาวอภิญญา พงศ์พูนทรัพย์ | D33: 98.5
A34: =SUBTOTAL(3,$B$5:$B34)*1 -> 30 | B34: 63550 | C34: นางสาวกชกร ไขว้เครือ | D34: 93.5
A35: =SUBTOTAL(3,$B$5:$B35)*1 -> 31 | B35: 63564 | C35: นางสาวสินีนาถ สงวนศรี | D35: 84/95 | N35: =VLOOKUP(B35,'1B 1A ครั้งที่ 1'!$B$4:$J$53,9,0) -> ซ่อมผ่าน
A36: =SUBTOTAL(3,$B$5:$B36)*1 -> 32 | B36: 63567 | C36: นางสาวสุจิตรา ภูพันนา | D36: 98
A37: =SUBTOTAL(3,$B$5:$B37)*1 -> 33 | B37: 63652 | C37: นางสาวสุดารัตน์ คูณศรี | D37: 93.5
A38: =SUBTOTAL(3,$B$5:$B38)*1 -> 34 | B38: 63658 | C38: นางสาวนัฐรดี เสนาปัก | D38: 96.5
A39: =SUBTOTAL(3,$B$5:$B39)*1 -> 35 | B39: 64312 | C39: นางสาวมินตรา เครือมาศ | D39: 94 | N39: อายุงานไม่ถึง 1 ปี
A40: =SUBTOTAL(3,$B$5:$B40)*1 -> 36 | B40: 64313 | C40: นางสาวภัทชนก จิตรประสงค์ | D40: 86.5/98 | N40: อายุงานไม่ถึง 1 ปี
...

Sheet สรุปผลแผนงาน
B1: สรุปผลแผนงาน ELITE TEAM KPD -DMK ประจำปี 2568
B2: พนักงานทั้งหมด
B3: ระดับ | C3: จำนวนพนักงานทั้งหมด | D3: ผ่านเกณฑ์ 90% | H3: หมายเหตุ
D4: ผ่าน ( คน ) | E4: คิดเป็น % | F4: ซ่อมผ่าน ( คน ) | G4: คิดเป็น %
B5: 2C | C5: 17 | E5: =D5/C5 -> 0 | G5: =F5/C5 -> 0
B6: 1A , 1B | C6: 37 | E6: =D6/C6 -> 0 | G6: =F6/C6 -> 0
B7: รวม | C7: =SUM(C5:C6) -> 54 | D7: =SUM(D5:D6) -> 0 | E7: =D7/C7 -> 0 | F7: =SUM(F5:F6) -> 0 | G7: =F7/C7 -> 0
B9: พนักงานที่เข้าร่วมโครงการ
B10: ระดับ | C10: จำนวนพนักงานทั้งหมด | D10: เข้าร่วมโครงการ | E10: ผ่านเกณฑ์ 90% | I10: ไม่ร่วมโครงการ | J10: หมายเหตุ
E11: ผ่าน ( คน ) | F11: คิดเป็น % | G11: ซ่อมผ่าน ( คน ) | H11: คิดเป็น %
B12: 2C | C12: 17 | D12: 17 | F12: =E12/D12 -> 0 | H12: =G12/D12 -> 0 | I12: -
B13: 1A , 1B | C13: 37 | D13: 33 | F13: =E13/D13 -> 0 | H13: =G13/D13 -> 0 | I13: 4
B14: รวม | C14: =SUM(C12:C13) -> 54 | D14: =SUM(D12:D13) -> 50 | E14: =SUM(E12:E13) -> 0 | F14: =E14/D14 -> 0 | G14: =SUM(G12:G13) -> 0 | H14: =G14/D14 -> 0 | I14: =SUM(I12:I13) -> 4
